<?xml version='1.0' encoding='utf-8'?>
<mujoco model="ur3">
  <option gravity="0 0 0" />
  <visual>
    <global offwidth="2048" offheight="1536" />
  </visual>

  
  <compiler angle="radian" />

  <asset>
    <!-- <texture name="skybox" type="skybox" builtin="gradient" rgb1="1 1 1" rgb2="1 1 1" width="800" height="800" /> -->
    <material name="gray" rgba="0.6 0.6 0.6 1.0" />
    <material name="LightGrey" rgba="0.7 0.7 0.7 1.0" />
    <material name="default_material" rgba="0.7 0.7 0.7 1" />
    <material name="collision_material" rgba="0.7 0.7 0.7 0.9" />
    <mesh name="base.stl" file="meshes/base.stl" />
    <mesh name="shoulder.stl" file="meshes/shoulder.stl" />
    <mesh name="upperarm.stl" file="meshes/upperarm.stl" />
    <mesh name="forearm.stl" file="meshes/forearm.stl" />
    <mesh name="wrist1.stl" file="meshes/wrist1.stl" />
    <mesh name="wrist2.stl" file="meshes/wrist2.stl" />
    <mesh name="wrist3.stl" file="meshes/wrist3.stl" />
  </asset>

  <worldbody>
    <light name="top" ambient="1 1 1" pos="0 0 7" />
    
    <body name="box_base" pos="0 0 0" quat="1 0 0 0">
      <freejoint name="free_joint" />
      <inertial pos="0.0 0.0 0" quat="1.0 0.0 0.0 0.0" mass="5.0" diaginertia="0.008 0.008 0.01" />
      <geom name="box_base_collision" pos="0 0 0" quat="1 0 0 0" type="box" size="0.0625 0.0625 0.0625" rgba="0.2 0.1 0.7 0.5" group="2" />
      <body name="base_link" pos="0 0 0.0625" quat="1.0 0.0 0.0 0.0">
        <inertial pos="0.0 0.0 0.0" quat="1.0 0.0 0.0 0.0" mass="2.0" diaginertia="0.0030531654454 0.0030531654454 0.005625" />
        <geom name="base_link_collision" pos="0 0 0" quat="1 0 0 0" type="mesh" mesh="base.stl" />
        <body name="shoulder_link" pos="0.0 0.0 0.1519" quat="1.0 0.0 0.0 0.0">
          <joint name="shoulder_pan_joint" type="hinge" ref="0.0" range="-6.28318530718 6.28318530718" axis="0 0 1" />
          <inertial pos="0.0 0.0 0.0" quat="1.0 0.0 0.0 0.0" mass="2.0" diaginertia="0.0080931634294 0.0080931634294 0.005625" />
          <geom name="shoulder_link_collision" pos="0 0 0" quat="1 0 0 0" type="mesh" mesh="shoulder.stl" />
          <body name="upper_arm_link" pos="0.0 0.1198 0.0" quat="0.7071067811882787 0.0 0.7071067811848163 0.0">
            <joint name="shoulder_lift_joint" type="hinge" ref="0.0" range="-4.014257279586958 0.6981317007977318" axis="0 1 0" />
            <inertial pos="0.0 0.0 0.121825" quat="1.0 0.0 0.0 0.0" mass="3.42" diaginertia="0.0217284832211 0.0217284832211 0.00961875" />
            <geom name="upper_arm_link_collision" pos="0 0 0" quat="1 0 0 0" type="mesh" mesh="upperarm.stl" />
            <body name="forearm_link" pos="0.0 -0.0925 0.24365" quat="1.0 0.0 0.0 0.0">
              <joint name="elbow_joint" type="hinge" ref="0.0" range="-2.443460952792061 2.0943951023931953" axis="0 1 0" />
              <inertial pos="0.0 0.0 0.106625" quat="1.0 0.0 0.0 0.0" mass="1.26" diaginertia="0.00654680644378 0.00654680644378 0.00354375" />
              <geom name="forearm_link_collision" pos="0 0 0" quat="1 0 0 0" type="mesh" mesh="forearm.stl" />
              <body name="wrist_1_link" pos="0.0 0.0 0.21325" quat="0.7071067811882787 0.0 0.7071067811848163 0.0">
                <joint name="wrist_1_joint" type="hinge" ref="0.0" range="-3.6651914291880923 0.5235987755982988" axis="0 1 0" />
                <inertial pos="0.0 0.0 0.0" quat="1.0 0.0 0.0 0.0" mass="0.8" diaginertia="0.002084999166 0.002084999166 0.00225" />
                <geom name="wrist_1_link_collision" pos="0 0 0" quat="1 0 0 0" type="mesh" mesh="wrist1.stl" />
                <body name="wrist_2_link" pos="0.0 0.08505 0.0" quat="1.0 0.0 0.0 0.0">
                  <joint name="wrist_2_joint" type="hinge" ref="0.0" range="-6.28318530718 6.28318530718" axis="0 0 1" />
                  <inertial pos="0.0 0.0 0.0" quat="1.0 0.0 0.0 0.0" mass="0.8" diaginertia="0.002084999166 0.002084999166 0.00225" />
                  <geom name="wrist_2_link_collision" pos="0 0 0" quat="1 0 0 0" type="mesh" mesh="wrist2.stl" />
                  <body name="wrist_3_link" pos="0.0 0.0 0.08535" quat="1.0 0.0 0.0 0.0">
                    <joint name="wrist_3_joint" type="hinge" ref="0.0" range="-6.28318530718 6.28318530718" axis="0 1 0" />
                    <inertial pos="0.0 0.0 0.0" quat="1.0 0.0 0.0 0.0" mass="0.35" diaginertia="0.000912187135125 0.000912187135125 0.000984375" />
                    <geom name="wrist_3_link_collision" pos="0 0 0" quat="1 0 0 0" type="mesh" mesh="wrist3.stl" />
                    <body name="camera_link" euler="4.712 0 3.14" pos="0 0.08535 0">
                      <inertial pos="0 0 0.01" mass="0.05" diaginertia="0.0 0.0 0.0" />
                      <geom name="camera_link_collision" pos="0 0 0.01" euler="3.14 0 3.14" type="box" rgba="0.2 0.7 0.1 0.5" size="0.01 0.01 0.01" />
                      <camera name="body_camera" pos="0 0 0" euler="3.14 0 0" /> 
                      <site name="camera_site" pos="0 0 0" euler="0 0 0" />
                      
                    <!-- <geom name="camera_link_collision_capsule" type="capsule" fromto="0.0099999873 -1.5926529e-05 0.01 -0.0099999873 1.5926529e-05 0.01" size="0.01" rgba="0.2 0.7 0.1 0.3" /> -->
                    </body>
                    <geom name="wrist_stack_collision_capsule"
                      type="capsule"
                      fromto="0 -0.03 0   0 0.08 0"
                      size="0.035"
                      rgba="0.2 0.7 0.1 0.3" /> 
                  <!-- <geom name="wrist_3_link_collision_capsule" type="capsule" fromto="-4.9163306e-05 0.060048751 -0.033820651 -4.9163306e-05 0.060048751 0.035812832" size="0.037207114" rgba="0.2 0.7 0.1 0.3"/> -->
                  </body>
                <!-- <geom name="wrist_2_link_collision_capsule" type="capsule" fromto="3.9895536e-06 -0.0024599063 0.038643956 3.9895536e-06 -0.0024599063 0.11545838" size="0.053393064" rgba="0.2 0.7 0.1 0.3" /> -->
                   
              </body>
              <geom name="wrist_1_link_collision_capsule"
                    type="capsule"
                    fromto="0 -0.02 0   0 0.09 0"
                    size="0.055"
                    rgba="0.2 0.7 0.1 0.3" />
              </body>
            <geom name="forearm_link_collision_capsule" 
            type="capsule" 
            fromto="0 0 0 0 0  0.24" 
            size="0.04" 
            rgba="0.2 0.7 0.1 0.3" />
            </body>
          <geom name="upper_arm_link_collision_capsule" type="capsule" fromto="-5.3875294e-06 -0.0033353008 -0.045880198 -5.3875294e-06 -0.0033353008 0.28237382" size="0.076983636" rgba="0.2 0.7 0.1 0.3"/>
          </body>
        <!-- <geom name="shoulder_link_collision_capsule" type="capsule" fromto="-5.7047309e-07 0.0073550706 -0.065851182 -5.7047309e-07 0.0073550706 0.057071529" size="0.064826769" rgba="0.2 0.7 0.1 0.3"/> -->
        </body>
      <!-- <geom name="base_link_collision_capsule" type="capsule" fromto="3.7999193e-05 -0.099491768 0.045762717 3.7999193e-05 0.063999951 0.045762717" size="0.078718612" rgba="0.2 0.7 0.1 0.3"/> -->
      </body>
    <!-- <geom name="box_base_collision_capsule" type="capsule" fromto="-0.0625 0 0 0.0625 0 0" size="0.0625" rgba="0.2 0.7 0.1 0.3" /> -->
    <geom name="box_base_collision_capsule"
      type="capsule"
      fromto="0 0 -0.0625  0 0 0.215"
      size="0.095"
      rgba="0.2 0.7 0.1 0.3" />
  </body>
  </worldbody>

  <actuator>
  <general joint="free_joint" gear="1 0 0 0 0 0" gainprm="1 0 0" />
  <general joint="free_joint" gear="0 1 0 0 0 0" gainprm="1 0 0" />
  <general joint="free_joint" gear="0 0 1 0 0 0" gainprm="1 0 0" />
  <general joint="free_joint" gear="0 0 0 1 0 0" gainprm="1 0 0" />
  <general joint="free_joint" gear="0 0 0 0 1 0" gainprm="1 0 0" />
  <general joint="free_joint" gear="0 0 0 0 0 1" gainprm="1 0 0" />

  
  <motor joint="shoulder_pan_joint" ctrllimited="false" />
  <motor joint="shoulder_lift_joint" ctrllimited="false" />
  <motor joint="elbow_joint" ctrllimited="false" />
  <motor joint="wrist_1_joint" ctrllimited="false" />
  <motor joint="wrist_2_joint" ctrllimited="false" />
  <motor joint="wrist_3_joint" ctrllimited="false" />

  </actuator>
</mujoco>